Workbook

Sheet DurationM
B2: Year | C2: Benefit CF | E2: Input Section of Duration Calculation
B3: 1 | C3: 11683622
B4: =B3+1 -> 2 | C4: 12282307 | E4: First Discount Rate in Duration Table (Default is 5%) | H4: 0.0525
B5: =B4+1 -> 3 | C5: 12930973 | E5: Increment in Discount Rate in Duration Table (Default is 0.25%) | H5: 0.0025
B6: =B5+1 -> 4 | C6: 13693816 | E6: Timing of Benefit Payments (1=EOY, 0.5=MOY (default), 0=BOY) | H6: 0
B7: =B6+1 -> 5 | C7: 14783907
B8: =B7+1 -> 6 | C8: 15864835 | E8: Duration and Convexity
B9: =B8+1 -> 7 | C9: 16977187 | E9: Interest | F9: D=Duration | G9: D*=Effective Duration | H9: Effective Convexity
B10: =B9+1 -> 8 | C10: 18260270 | E10: {=INDEX(CalcM!G10:G12,L11)} -> 19.877122 | F10: 1 | G10: 2 | H10: 3
B11: =B10+1 -> 9 | C11: 19351600 | E11: =IF(H4="",5%,H4) -> 0.0525 | F11: 19.533072 | G11: 18.558738 | H11: 491.88691 | J11: index dummy | L11: 1
B12: =B11+1 -> 10 | C12: 20863277 | E12: =E11+IF($H$5="",0.25%,$H$5) -> 0.055 | F12: 19.193925 | G12: 18.193294 | H12: 475.89107 | J12: interest dummy | L12: 0.05
B13: =B12+1 -> 11 | C13: 22579574 | E13: =E12+IF($H$5="",0.25%,$H$5) -> 0.0575 | F13: 18.859733 | G13: 17.834263 | H13: 460.39101
B14: =B13+1 -> 12 | C14: 24504101 | E14: =E13+IF($H$5="",0.25%,$H$5) -> 0.06 | F14: 18.53054 | G14: 17.481642 | H14: 445.37523
B15: =B14+1 -> 13 | C15: 26318482 | E15: =E14+IF($H$5="",0.25%,$H$5) -> 0.0625 | F15: 18.206385 | G15: 17.135422 | H15: 430.83224
B16: =B15+1 -> 14 | C16: 28300403 | E16: =E15+IF($H$5="",0.25%,$H$5) -> 0.065 | F16: 17.887301 | G16: 16.795588 | H16: 416.75057
B17: =B16+1 -> 15 | C17: 30563624 | E17: =E16+IF($H$5="",0.25%,$H$5) -> 0.0675 | F17: 17.573313 | G17: 16.46212 | H17: 403.11879
B18: =B17+1 -> 16 | C18: 32754109 | E18: =E17+IF($H$5="",0.25%,$H$5) -> 0.07 | F18: 17.264441 | G18: 16.134991 | H18: 389.92552
B19: =B18+1 -> 17 | C19: 34693405 | E19: =E18+IF($H$5="",0.25%,$H$5) -> 0.0725 | F19: 16.960698 | G19: 15.814171 | H19: 377.15946
B20: =B19+1 -> 18 | C20: 37158439 | E20: =E19+IF($H$5="",0.25%,$H$5) -> 0.075 | F20: 16.662092 | G20: 15.499621 | H20: 364.80938
B21: =B20+1 -> 19 | C21: 39151446 | E21: =E20+IF($H$5="",0.25%,$H$5) -> 0.0775 | F21: 16.368626 | G21: 15.1913 | H21: 352.86415
B22: =B21+1 -> 20 | C22: 40880133 | E22: =E21+IF($H$5="",0.25%,$H$5) -> 0.08 | F22: 16.080295 | G22: 14.889162 | H22: 341.31275
B23: =B22+1 -> 21 | C23: 42870412 | E23: =E22+IF($H$5="",0.25%,$H$5) -> 0.0825 | F23: 15.797089 | G23: 14.593154 | H23: 330.14427
B24: =B23+1 -> 22 | C24: 45007659 | E24: =E23+IF($H$5="",0.25%,$H$5) -> 0.085 | F24: 15.518996 | G24: 14.303222 | H24: 319.34792
B25: =B24+1 -> 23 | C25: 46548197
B26: =B25+1 -> 24 | C26: 48004382 | E26: D = Duration | F26: Effective Maturity by Frederick Macaulay
B27: =B26+1 -> 25 | C27: 49356321 | F27: Weighted Average of the times to each coupon or principal payment made by the bond.
B28: =B27+1 -> 26 | C28: 50270765 | F28: The duration of the zero-coupon bond is exactly equal to its time to maturity
B29: =B28+1 -> 27 | C29: 50907520 | E29: D* = Eff. Duration | F29: Effective Duration or Modified Duration
B30: =B29+1 -> 28 | C30: 51125265 | F30: Sensitivity of security price to interest rate change
B31: =B30+1 -> 29 | C31: 51169152 | F31: Percentage change in security price is just a byproduct of the effective duration
B32: =B31+1 -> 30 | C32: 50911981 | F32: and the change in the security yield to maturity
B33: =B32+1 -> 31 | C33: 50468544 | F33: =(PriceDown - PriceUp) / (Price * Delta) = - (Price Derivative) / Price
B34: =B33+1 -> 32 | C34: 49742852 | E34: Relation of D and D* | F34: Effective duration = Duration / (1+i) or Duration = Effective Duration * (1+i)
B35: =B34+1 -> 33 | C35: 48841140 | E35: Effective Convexity | F35: =(PriceDown - 2*Price + PriceUp) / (P * Delta^2)
B36: =B35+1 -> 34 | C36: 47675927
B37: =B36+1 -> 35 | C37: 46192160
B38: =B37+1 -> 36 | C38: 44435243
B39: =B38+1 -> 37 | C39: 42484026
B40: =B39+1 -> 38 | C40: 40381734
B41: =B40+1 -> 39 | C41: 38145904
...

Sheet CalcM
B2: Duration Input Section
B4: Discount Rate | G4: =IF(DurationM!L12="",5%,DurationM!L12) -> 0.05
B5: Timing of Benefit Payments (1=EOY, 0.5=MOY, 0=BOY) | G5: =IF(DurationM!H6="",0.5,DurationM!H6) -> 0
B7: Duration Output Summary
B9: P = Present Value | G9: =E20 -> 5.4338777e+08
B10: D = Duration | G10: =F20/E20 -> 19.877122
B11: D* = Effective Duration | G11: =G10/(1+G4) -> 18.930593
B12: Effective Convexity | G12: =G20/E20/(1+G4)^2 -> 508.39004
B14: Duration Calculation Details
B15: Discount Rate | G15: =IF(G4="",5%,G4) -> 0.05
B16: Timing | G16: =IF(G5="",0.5,G5) -> 0
E18: Discounted Values
B19: Year | C19: Input Benefits | E19: P(i) | F19: t*P(i) | G19: t*(t_1)*P(i)
D20: Total | E20: =SUM(E21:E140) -> 5.4338777e+08 | F20: =SUM(F21:F140) -> 1.0800985e+10 | G20: =SUM(G21:G140) -> 3.0456886e+11
B21: 1 | C21: =DurationM!C3 -> 11683622 | D21: =G5 -> 0 | E21: =C21/(1+$G$4)^D21 -> 11683622 | F21: =D21*E21 -> 0 | G21: =F21*(1+D21) -> 0
B22: 2 | C22: =DurationM!C4 -> 12282307 | D22: =D21+1 -> 1 | E22: =C22/(1+$G$4)^D22 -> 11697435 | F22: =D22*E22 -> 11697435 | G22: =F22*(1+D22) -> 23394870
B23: 3 | C23: =DurationM!C5 -> 12930973 | D23: =D22+1 -> 2 | E23: =C23/(1+$G$4)^D23 -> 11728774 | F23: =D23*E23 -> 23457547 | G23: =F23*(1+D23) -> 70372642
B24: 4 | C24: =DurationM!C6 -> 13693816 | D24: =D23+1 -> 3 | E24: =C24/(1+$G$4)^D24 -> 11829233 | F24: =D24*E24 -> 35487699 | G24: =F24*(1+D24) -> 1.419508e+08
B25: 5 | C25: =DurationM!C7 -> 14783907 | D25: =D24+1 -> 4 | E25: =C25/(1+$G$4)^D25 -> 12162757 | F25: =D25*E25 -> 48651028 | G25: =F25*(1+D25) -> 2.4325514e+08
B26: 6 | C26: =DurationM!C8 -> 15864835 | D26: =D25+1 -> 5 | E26: =C26/(1+$G$4)^D26 -> 12430513 | F26: =D26*E26 -> 62152567 | G26: =F26*(1+D26) -> 3.729154e+08
B27: 7 | C27: =DurationM!C9 -> 16977187 | D27: =D26+1 -> 6 | E27: =C27/(1+$G$4)^D27 -> 12668638 | F27: =D27*E27 -> 76011830 | G27: =F27*(1+D27) -> 5.3208281e+08
B28: 8 | C28: =DurationM!C10 -> 18260270 | D28: =D27+1 -> 7 | E28: =C28/(1+$G$4)^D28 -> 12977233 | F28: =D28*E28 -> 90840631 | G28: =F28*(1+D28) -> 7.2672505e+08
B29: 9 | C29: =DurationM!C11 -> 19351600 | D29: =D28+1 -> 8 | E29: =C29/(1+$G$4)^D29 -> 13097925 | F29: =D29*E29 -> 1.047834e+08 | G29: =F29*(1+D29) -> 9.4305057e+08
B30: 10 | C30: =DurationM!C12 -> 20863277 | D30: =D29+1 -> 9 | E30: =C30/(1+$G$4)^D30 -> 13448654 | F30: =D30*E30 -> 1.2103789e+08 | G30: =F30*(1+D30) -> 1.2103789e+09
B31: 11 | C31: =DurationM!C13 -> 22579574 | D31: =D30+1 -> 10 | E31: =C31/(1+$G$4)^D31 -> 13861900 | F31: =D31*E31 -> 1.38619e+08 | G31: =F31*(1+D31) -> 1.524809e+09
B32: 12 | C32: =DurationM!C14 -> 24504101 | D32: =D31+1 -> 11 | E32: =C32/(1+$G$4)^D32 -> 14327040 | F32: =D32*E32 -> 1.5759744e+08 | G32: =F32*(1+D32) -> 1.8911693e+09
B33: 13 | C33: =DurationM!C15 -> 26318482 | D33: =D32+1 -> 12 | E33: =C33/(1+$G$4)^D33 -> 14655116 | F33: =D33*E33 -> 1.7586139e+08 | G33: =F33*(1+D33) -> 2.286198e+09
... B140: 120 | C140: =DurationM!C122 -> 0 | D140: =D139+1 -> 119 | E140: =C140/(1+$G$4)^D140 -> 0 | F140: =D140*E140 -> 0 | G140: =F140*(1+D140) -> 0
